<?xml version="1.0" ?>
<!-- 
*****************************************************************************************
*
*        =============================================
*                  HB Theme (eYRC 2023-24)
*        =============================================
*
*
*  Filename:            hb_bot.urdf.xacro
*  Created:             
*  Last Modified:       
*  Author:              
*  
*****************************************************************************************
-->


<robot name="hb_bot" xmlns:xacro="http://www.ros.org/wiki/xacro">
    <xacro:include filename="$(find hb_task_1b)/urdf/materials.xacro"/>
    
    <link name ="footprint_link">
    </link>
    <joint name="footprint_joint" type="fixed">
         <origin
                xyz="0.0 0.0 0.0"
                rpy="0 0 0" />
        <parent link="footprint_link"/>
        <child link="base_link"/>
        
        
    </joint>

    <!--Base link-->
    <link name ="base_link">
        <inertial>
            <origin xyz="0 0.0 0.28" rpy="0 0 0" />
            <mass
                value="0.28" />
            <inertia
                ixx="0.011666666666667"
                ixy="0"
                ixz="0"
                iyy="0.011666666666667"
                iyz="0"
                izz="0.011666666666667" />    

        </inertial>
         <collision name="collision">
            <origin
                xyz="0 0.0 0.28"
                rpy="0 0 0" />
          
            <geometry>
                <mesh filename ="file://$(find hb_task_1b)/meshes/base.dae" scale="0.01  0.01 0.01"/>
                    
            </geometry>
        </collision>
        <visual>
            <origin
                xyz="0 0 0.28"
                rpy="0 0 0" />
            <geometry>
                <mesh 
                filename ="file://$(find hb_task_1b)/meshes/base.dae" scale="0.01  0.01 0.01"/>
            </geometry>
        </visual>
    </link>
    <!-- right_wheel -->

    <link name ="right_wheel">
 
        <inertial>
            <origin
                xyz="0 -0.05 0.0"
                rpy="1.57 0 0" />
            <mass
                value="0.060" />
            <inertia
                ixx="1.825e-4"
                ixy="0"
                ixz="0.00000000"
                iyy="1.825e-4"
                iyz="0"
                izz="1.825e-4" />       
        </inertial>
         <collision name="R_collision">
         <origin
                xyz="0 -0.05 0.0"
                rpy="1.57 0 0" />
          <geometry>
            <cylinder length="0.13" radius="0.14"/>
          </geometry>
        </collision>

        <visual>
            <origin
            xyz="0.0 0.0 0.0"
            rpy="0.0 0.0 0.0" />
            <geometry>
                <mesh filename ="file://$(find hb_task_1b)/meshes/wheel.stl" scale="5 5 5"/>
            </geometry>
           
        </visual>
    </link>

    <!-- Joint -->
    <joint name ="right_wheel_joint" type="continuous" >
        <origin
                xyz="0.0 0.68 0.18"
                rpy="0 0 0" />
        <parent link="base_link"/>
        <child link="right_wheel"/>
        <axis xyz="0.0 1.0 0.0"/>
         <limit
            effort="5"
            velocity="5" />
    </joint>

    <!-- material properties -->
    <gazebo reference="right_wheel">
        <material>Gazebo/Black</material>
    </gazebo>

    
</robot>

